相对于可选中运用值的存在与缺失来表达函数的成功与失败，错误处理可以推断失败的原因，并传播至程序的其他部分。

### throws关键词
一个函数可以通过在声明中添加throws关键词来抛出错误消息。
```
  func canThrowAnError() throws {
    // 这个函数有可能抛出错误
  }
```

### try关键词
当你的函数可能抛出错误消息时, 调用函数时前置try关键词。
```
  try canThrowAnError()
```

### do...catch语句
一个do语句创建了一个新的包含作用域,使得错误能被传播到一个或多个catch从句。

#### eg1:
```
do {
    try canThrowAnError()
    // 没有错误消息抛出
} catch {
    // 有一个错误消息抛出
}
``` 

#### eg2:
```
  func makeASandwich() throws {
      // ...
  }

  do {
      try makeASandwich()
      eatASandwich()
  } catch SandwichError.outOfCleanDishes {
      washDishes()
  } catch SandwichError.missingIngredients(let ingredients) {
      buyGroceries(ingredients)
  }
```

因为 makeASandwich() 抛出错误，函数调用被包裹在 try 表达式中。将函数包裹在一个 do 语句中，任何被抛出的错误会被传播到提供的 catch 从句中。

如果没有错误被抛出，eatASandwich() 函数会被调用。如果一个匹配 SandwichError.outOfCleanDishes 的错误被抛出，washDishes() 函数会被调用。如果一个匹配 SandwichError.missingIngredients 的错误被抛出，buyGroceries(_:) 函数会被调用，并且使用 catch 所捕捉到的关联值 [String] 作为参数。